Workbook

Sheet 01_Raw_Data
A1: OrderID | B1: Date | C1: CustomerID | D1: Product | E1: Quantity | F1: UnitPrice | G1: ShippingAddress | H1: PaymentMethod | I1: OrderStatus | J1: TrackingNumber | K1: ItemsInCart | L1: CouponCode | M1: ReferralSource | N1: TotalPrice
A2: ORD200000 | B2: 44930 | C2: C72649 | D2: Monitor | E2: 5 | F2: 570.62 | G2: 928 Main St | H2: Debit Card | I2: Shipped | J2: TRK37947903 | K2: 7 | L2: SAVE10 | M2: Instagram | N2: 2853.1
A3: ORD200001 | B3: 45527 | C3: C75739 | D3: Phone | E3: 2 | F3: 151.35 | G3: 823 Main St | H3: Online | I3: Shipped | J3: TRK91186779 | K3: 3 | L3: SAVE10 | M3: Referral | N3: 302.7
A4: ORD200002 | B4: 45349 | C4: C81728 | D4: Tablet | E4: 5 | F4: 550.68 | G4: 512 Main St | H4: Credit Card | I4: Cancelled | J4: TRK42903982 | K4: 8 | L4: FREESHIP | M4: Email | N4: 2753.4
A5: ORD200003 | B5: 45214 | C5: C33540 | D5: Chair | E5: 1 | F5: 273.19 | G5: 275 Main St | H5: Debit Card | I5: Returned | J5: TRK62788070 | K5: 5 | L5: SAVE10 | M5: Facebook | N5: 273.19
A6: ORD200004 | B6: 45785 | C6: C81840 | D6: Printer | E6: 4 | F6: 626.01 | G6: 668 Main St | H6: Online | I6: Delivered | J6: TRK29241424 | K6: 8 | L6: SAVE10 | M6: Email | N6: 2504.04
A7: ORD200005 | B7: 45222 | C7: C37249 | D7: Phone | E7: 2 | F7: 245.86 | G7: 934 Main St | H7: Credit Card | I7: Shipped | J7: TRK72976927 | K7: 4 | L7: SAVE10 | M7: Instagram | N7: 491.72
A8: ORD200006 | B8: 45825 | C8: C83492 | D8: Laptop | E8: 1 | F8: 664.42 | G8: 986 Main St | H8: Gift Card | I8: Returned | J8: TRK96417362 | K8: 6 | L8: SAVE10 | M8: Facebook | N8: 664.42
A9: ORD200007 | B9: 45058 | C9: C41460 | D9: Monitor | E9: 5 | F9: 149.55 | G9: 706 Main St | H9: Cash | I9: Shipped | J9: TRK78809193 | K9: 9 | L9: FREESHIP | M9: Facebook | N9: 747.75
A10: ORD200008 | B10: 45749 | C10: C26817 | D10: Phone | E10: 2 | F10: 134.28 | G10: 904 Main St | H10: Gift Card | I10: Cancelled | J10: TRK61042692 | K10: 2 | M10: Email | N10: 268.56
A11: ORD200009 | B11: 45251 | C11: C31946 | D11: Desk | E11: 4 | F11: 509.38 | G11: 102 Main St | H11: Credit Card | I11: Shipped | J11: TRK33478363 | K11: 6 | L11: SAVE10 | M11: Google | N11: 2037.52
A12: ORD200010 | B12: 45289 | C12: C43443 | D12: Tablet | E12: 5 | F12: 625.97 | G12: 333 Main St | H12: Credit Card | I12: Returned | J12: TRK98859248 | K12: 9 | L12: WINTER15 | M12: Instagram | N12: 3129.85
A13: ORD200011 | B13: 45339 | C13: C93861 | D13: Monitor | E13: 3 | F13: 49.14 | G13: 831 Main St | H13: Online | I13: Returned | J13: TRK48234646 | K13: 7 | L13: SAVE10 | M13: Email | N13: 147.42
A14: ORD200012 | B14: 45580 | C14: C38785 | D14: Monitor | E14: 2 | F14: 180.5 | G14: 179 Main St | H14: Debit Card | I14: Pending | J14: TRK20419991 | K14: 6 | L14: FREESHIP | M14: Referral | N14: 361
A15: ORD200013 | B15: 45168 | C15: C88348 | D15: Laptop | E15: 3 | F15: 201.49 | G15: 903 Main St | H15: Credit Card | I15: Returned | J15: TRK81913874 | K15: 4 | L15: FREESHIP | M15: Facebook | N15: 604.47
A16: ORD200014 | B16: 45012 | C16: C98474 | D16: Tablet | E16: 2 | F16: 393.33 | G16: 980 Main St | H16: Debit Card | I16: Pending | J16: TRK79186539 | K16: 3 | L16: SAVE10 | M16: Instagram | N16: 786.66
A17: ORD200015 | B17: 45124 | C17: C39416 | D17: Printer | E17: 1 | F17: 473.96 | G17: 942 Main St | H17: Cash | I17: Delivered | J17: TRK54930938 | K17: 3 | M17: Google | N17: 473.96
A18: ORD200016 | B18: 44950 | C18: C28976 | D18: Printer | E18: 2 | F18: 533.81 | G18: 914 Main St | H18: x | I18: Pending | J18: TRK13194259 | K18: 3 | L18: FREESHIP | M18: Email | N18: 1067.62
A19: ORD200017 | B19: 45353 | C19: C60672 | D19: Tablet | E19: 1 | F19: 423.4 | G19: 382 Main St | H19: Debit Card | I19: Shipped | J19: TRK11972116 | K19: 3 | M19: Referral | N19: 423.4
A20: ORD200018 | B20: 45742 | C20: C84329 | D20: Desk | E20: 1 | F20: 431.44 | G20: 891 Main St | H20: Gift Card | I20: Pending | J20: TRK65191045 | K20: 3 | L20: SAVE10 | M20: Facebook | N20: 431.44
A21: ORD200019 | B21: 44949 | C21: C14552 | D21: Monitor | E21: 5 | F21: 224 | G21: 273 Main St | H21: Cash | I21: Returned | J21: TRK59101365 | K21: 9 | L21: SAVE10 | M21: Google | N21: 1120
A22: ORD200020 | B22: 45054 | C22: C54829 | D22: Chair | E22: 5 | F22: 62.51 | G22: 587 Main St | H22: Cash | I22: Pending | J22: TRK16718651 | K22: 9 | L22: WINTER15 | M22: Instagram | N22: 312.55
A23: ORD200021 | B23: 45613 | C23: C99023 | D23: Monitor | E23: 4 | F23: 342.95 | G23: 569 Main St | H23: Cash | I23: Delivered | J23: TRK52646983 | K23: 6 | M23: Google | N23: 1371.8
A24: ORD200022 | B24: 44955 | C24: C34416 | D24: Monitor | E24: 2 | F24: 49.62 | G24: 633 Main St | H24: Online | I24: Pending | J24: TRK75937350 | K24: 2 | L24: SAVE10 | M24: Google | N24: 99.24
A25: ORD200023 | B25: 45756 | C25: C42372 | D25: Phone | E25: 4 | F25: 273.25 | G25: 755 Main St | H25: Debit Card | I25: Cancelled | J25: TRK36168083 | K25: 5 | L25: FREESHIP | M25: Referral | N25: 1093
A26: ORD200024 | B26: 45595 | C26: C17470 | D26: Laptop | E26: 2 | F26: 230.95 | G26: 956 Main St | H26: Online | I26: Delivered | J26: TRK28775057 | K26: 3 | L26: WINTER15 | M26: Referral | N26: 461.9
A27: ORD200025 | B27: 45497 | C27: C42577 | D27: Monitor | E27: 1 | F27: 399.98 | G27: 709 Main St | H27: Debit Card | I27: Delivered | J27: TRK69423327 | K27: 3 | L27: WINTER15 | M27: Email | N27: 399.98
A28: ORD200026 | B28: 45357 | C28: C21944 | D28: Laptop | E28: 5 | F28: 59.55 | G28: 296 Main St | H28: Online | I28: Delivered | J28: TRK80276812 | K28: 6 | M28: Referral | N28: 297.75
A29: ORD200027 | B29: 45344 | C29: C97593 | D29: Printer | E29: 1 | F29: 472.74 | G29: 881 Main St | H29: Online | I29: Shipped | J29: TRK89117573 | K29: 6 | L29: WINTER15 | M29: Google | N29: 472.74
A30: ORD200028 | B30: 45251 | C30: C59823 | D30: Phone | E30: 4 | F30: 160.07 | G30: 568 Main St | H30: Online | I30: Pending | J30: TRK65895539 | K30: 5 | M30: Email | N30: 640.28
A31: ORD200029 | B31: 45555 | C31: C33260 | D31: Desk | E31: 3 | F31: 423.53 | G31: 930 Main St | H31: Credit Card | I31: Delivered | J31: TRK59744090 | K31: 6 | L31: SAVE10 | M31: Referral | N31: 1270.59
A32: ORD200030 | B32: 45738 | C32: C44267 | D32: Monitor | E32: 2 | F32: 426.7 | G32: 895 Main St | H32: Online | I32: Pending | J32: TRK54751444 | K32: 5 | L32: SAVE10 | M32: Referral | N32: 853.4
A33: ORD200031 | B33: 45107 | C33: C26445 | D33: Chair | E33: 3 | F33: 500.08 | G33: 996 Main St | H33: Debit Card | I33: Returned | J33: TRK31229981 | K33: 6 | M33: Facebook | N33: 1500.24
A34: ORD200032 | B34: 45047 | C34: C12388 | D34: Tablet | E34: 5 | F34: 536.72 | G34: 830 Main St | H34: Cash | I34: Delivered | J34: TRK99261395 | K34: 10 | M34: Email | N34: 2683.6
A35: ORD200033 | B35: 45082 | C35: C52184 | D35: Chair | E35: 1 | F35: 162.77 | G35: 912 Main St | H35: Online | I35: Cancelled | J35: TRK73312471 | K35: 4 | L35: WINTER15 | M35: Facebook | N35: 162.77
A36: ORD200034 | B36: 44933 | C36: C67195 | D36: Chair | E36: 4 | F36: 576.52 | G36: 926 Main St | H36: Credit Card | I36: Pending | J36: TRK55467915 | K36: 5 | L36: WINTER15 | M36: Facebook | N36: 2306.08
A37: ORD200035 | B37: 45633 | C37: C50304 | D37: Monitor | E37: 2 | F37: 465.15 | G37: 128 Main St | H37: Online | I37: Shipped | J37: TRK46850888 | K37: 2 | L37: SAVE10 | M37: Facebook | N37: 930.3
A38: ORD200036 | B38: 45785 | C38: C59337 | D38: Laptop | E38: 2 | F38: 534.43 | G38: 465 Main St | H38: Debit Card | I38: Pending | J38: TRK50961250 | K38: 5 | M38: Facebook | N38: 1068.86
A39: ORD200037 | B39: 45579 | C39: C10054 | D39: Laptop | E39: 2 | F39: 76.74 | G39: 409 Main St | H39: Cash | I39: Returned | J39: TRK94005261 | K39: 7 | L39: SAVE10 | M39: Instagram | N39: 153.48
A40: ORD200038 | B40: 45645 | C40: C15924 | D40: Laptop | E40: 1 | F40: 245.89 | G40: 549 Main St | H40: Debit Card | I40: Delivered | J40: TRK14835975 | K40: 3 | L40: SAVE10 | M40: Google | N40: 245.89
...

Sheet 02_Aggregate_FunTable
A2: Total Sales by Product-wise Aggregation Analysis | H2: {=_xlfn.UNIQUE('01_Raw_Data'!D2:D1201)} -> Monitor
H3: Phone
A4: Product | B4: Total Sales | C4: Quantity | D4: UnitPrice | H4: Tablet
A5: Chair | B5: =SUMIF('01_Raw_Data'!D2:D1201,'02_Aggregate_FunTable'!A5,'01_Raw_Data'!N2:N1201) -> 195620.11 | C5: =SUMIF('01_Raw_Data'!D2:D1201,'02_Aggregate_FunTable'!A5,'01_Raw_Data'!E2:E1201) -> 562 | D5: =AVERAGEIF('01_Raw_Data'!D2:D1201,'02_Aggregate_FunTable'!A5,'01_Raw_Data'!F2:F1201) -> 355.66028 | H5: Chair
H6: Printer
H7: Laptop
A8: Payment Method-wise Sales Analysis | H8: Desk
A10: Payment Method | B10: Total Sales
A11: Gift Card | B11: =SUMIF('01_Raw_Data'!H2:H1201,'02_Aggregate_FunTable'!A11,'01_Raw_Data'!N2:N1201) -> 246323.92

Sheet 03_IFERROR
A1: OrderID | B1: Product | C1: Quantity | D1: UnitPrice | E1: TotalPrice | F1: Average | G1: IF AVERAGE | H1: User define
A2: ORD200000 | B2: Monitor | C2: 5 | D2: 570.62 | E2: 2853.1 | F2: =AVERAGE(C2:E2) -> 1142.9067 | G2: {=IFERROR(F2:F20,"SOLVE")} -> 1142.9067 | H2: =IFERROR(AVERAGE(C2:E2),"Solve") -> 1142.9067
A3: ORD200001 | B3: Phone | C3: 2 | D3: 151.35 | E3: 302.7 | F3: =AVERAGE(C3:E3) -> 152.01667 | G3: 152.01667 | H3: =IFERROR(AVERAGE(C3:E3),"Solve") -> 152.01667
A4: ORD200002 | B4: Tablet | C4: 5 | D4: 550.68 | E4: 2753.4 | F4: =AVERAGE(C4:E4) -> 1103.0267 | G4: 1103.0267 | H4: =IFERROR(AVERAGE(C4:E4),"Solve") -> 1103.0267
A5: ORD200003 | B5: Chair | D5: 273.19 | E5: 273.19 | F5: =AVERAGE(C5:E5) -> 273.19 | G5: 273.19 | H5: =IFERROR(AVERAGE(C5:E5),"Solve") -> 273.19
A6: ORD200004 | B6: Printer | C6: 4 | D6: 626.01 | E6: 2504.04 | F6: =AVERAGE(C6:E6) -> 1044.6833 | G6: 1044.6833 | H6: =IFERROR(AVERAGE(C6:E6),"Solve") -> 1044.6833
A7: ORD200005 | B7: Phone | C7: 2 | D7: 245.86 | E7: 491.72 | F7: =AVERAGE(C7:E7) -> 246.52667 | G7: 246.52667 | H7: =IFERROR(AVERAGE(C7:E7),"Solve") -> 246.52667
A8: ORD200006 | B8: Laptop | C8: 1 | D8: 664.42 | E8: 664.42 | F8: =AVERAGE(C8:E8) -> 443.28 | G8: 443.28 | H8: =IFERROR(AVERAGE(C8:E8),"Solve") -> 443.28
A9: ORD200007 | B9: Monitor | F9: =AVERAGE(C9:E9) -> #DIV/0! | G9: SOLVE | H9: =IFERROR(AVERAGE(C9:E9),"Solve") -> Solve
A10: ORD200008 | B10: Phone | C10: 2 | D10: 134.28 | E10: 268.56 | F10: =AVERAGE(C10:E10) -> 134.94667 | G10: 134.94667 | H10: =IFERROR(AVERAGE(C10:E10),"Solve") -> 134.94667
A11: ORD200009 | B11: Desk | C11: 4 | D11: 509.38 | E11: 2037.52 | F11: =AVERAGE(C11:E11) -> 850.3 | G11: 850.3 | H11: =IFERROR(AVERAGE(C11:E11),"Solve") -> 850.3
A12: ORD200010 | B12: Tablet | C12: 5 | D12: 625.97 | E12: 3129.85 | F12: =AVERAGE(C12:E12) -> 1253.6067 | G12: 1253.6067 | H12: =IFERROR(AVERAGE(C12:E12),"Solve") -> 1253.6067
A13: ORD200011 | B13: Monitor | F13: =AVERAGE(C13:E13) -> #DIV/0! | G13: SOLVE | H13: =IFERROR(AVERAGE(C13:E13),"Solve") -> Solve
A14: ORD200012 | B14: Monitor | C14: 2 | D14: 180.5 | E14: 361 | F14: =AVERAGE(C14:E14) -> 181.16667 | G14: 181.16667 | H14: =IFERROR(AVERAGE(C14:E14),"Solve") -> 181.16667
A15: ORD200013 | B15: Laptop | C15: 3 | D15: 201.49 | E15: 604.47 | F15: =AVERAGE(C15:E15) -> 269.65333 | G15: 269.65333 | H15: =IFERROR(AVERAGE(C15:E15),"Solve") -> 269.65333
A16: ORD200014 | B16: Tablet | C16: 2 | D16: 393.33 | E16: 786.66 | F16: =AVERAGE(C16:E16) -> 393.99667 | G16: 393.99667 | H16: =IFERROR(AVERAGE(C16:E16),"Solve") -> 393.99667
A17: ORD200015 | B17: Printer | C17: 1 | D17: 473.96 | E17: 473.96 | F17: =AVERAGE(C17:E17) -> 316.30667 | G17: 316.30667 | H17: =IFERROR(AVERAGE(C17:E17),"Solve") -> 316.30667
A18: ORD200016 | B18: Printer | F18: =AVERAGE(C18:E18) -> #DIV/0! | G18: SOLVE | H18: =IFERROR(AVERAGE(C18:E18),"Solve") -> Solve
A19: ORD200017 | B19: Tablet | C19: 1 | D19: 423.4 | E19: 423.4 | F19: =AVERAGE(C19:E19) -> 282.6 | G19: 282.6 | H19: =IFERROR(AVERAGE(C19:E19),"Solve") -> 282.6
A20: ORD200018 | B20: Desk | C20: 1 | D20: 431.44 | E20: 431.44 | F20: =AVERAGE(C20:E20) -> 287.96 | G20: 287.96 | H20: =IFERROR(AVERAGE(C20:E20),"Solve") -> 287.96

Sheet 03_Normal_Table
A1: Normal Table
A3: Definition | B3: Organizes data into rows and columns with clear headings.
A4: Purpose | B4: Read, sort, filter, and manage data.
A6: Product | B6: Total Quantity
A8: Product | B8: Quantity
A9: {=_xlfn.UNIQUE('01_Raw_Data'!D2:D1201)} -> Monitor | B9: =SUMIF('01_Raw_Data'!D2:D1201,'03_Normal_Table'!A9,'01_Raw_Data'!E2:E1201) -> 480
A10: Phone | B10: =SUMIF('01_Raw_Data'!D3:D1202,'03_Normal_Table'!A10,'01_Raw_Data'!E3:E1202) -> 411
A11: Tablet | B11: =SUMIF('01_Raw_Data'!D4:D1203,'03_Normal_Table'!A11,'01_Raw_Data'!E4:E1203) -> 497
A12: Chair | B12: =SUMIF('01_Raw_Data'!D5:D1204,'03_Normal_Table'!A12,'01_Raw_Data'!E5:E1204) -> 562
A13: Printer | B13: =SUMIF('01_Raw_Data'!D6:D1205,'03_Normal_Table'!A13,'01_Raw_Data'!E6:E1205) -> 542
A14: Laptop | B14: =SUMIF('01_Raw_Data'!D7:D1206,'03_Normal_Table'!A14,'01_Raw_Data'!E7:E1206) -> 535
A15: Desk | B15: =SUMIF('01_Raw_Data'!D8:D1207,'03_Normal_Table'!A15,'01_Raw_Data'!E8:E1207) -> 508
A20: Product | B20: Total Sales
A21: {=_xlfn.UNIQUE('01_Raw_Data'!D2:D1201)} -> Monitor | B21: =SUMIF('01_Raw_Data'!D2:D1201,'03_Normal_Table'!A21,'01_Raw_Data'!N2:N1201) -> 175651.41
A22: Phone | B22: =SUMIF('01_Raw_Data'!D3:D1202,'03_Normal_Table'!A22,'01_Raw_Data'!N3:N1202) -> 151722.39
A23: Tablet | B23: =SUMIF('01_Raw_Data'!D4:D1203,'03_Normal_Table'!A23,'01_Raw_Data'!N4:N1203) -> 186568.95
A24: Chair | B24: =SUMIF('01_Raw_Data'!D5:D1204,'03_Normal_Table'!A24,'01_Raw_Data'!N5:N1204) -> 195620.11
A25: Printer | B25: =SUMIF('01_Raw_Data'!D6:D1205,'03_Normal_Table'!A25,'01_Raw_Data'!N6:N1205) -> 195612.61
A26: Laptop | B26: =SUMIF('01_Raw_Data'!D7:D1206,'03_Normal_Table'!A26,'01_Raw_Data'!N7:N1206) -> 192126.56
A27: Desk | B27: =SUMIF('01_Raw_Data'!D8:D1207,'03_Normal_Table'!A27,'01_Raw_Data'!N8:N1207) -> 167459.93
A34: Payment Method | B34: Total Sales
A35: {=_xlfn.UNIQUE('01_Raw_Data'!H2:H1201)} -> Debit Card | B35: =SUMIF('01_Raw_Data'!H2:H1201,'03_Normal_Table'!A35,'01_Raw_Data'!N2:N1201) -> 232361.18
A36: Online | B36: =SUMIF('01_Raw_Data'!H3:H1202,'03_Normal_Table'!A36,'01_Raw_Data'!N3:N1202) -> 262442.94
A37: Credit Card | B37: =SUMIF('01_Raw_Data'!H4:H1203,'03_Normal_Table'!A37,'01_Raw_Data'!N4:N1203) -> 262780.01
A38: Gift Card | B38: =SUMIF('01_Raw_Data'!H5:H1204,'03_Normal_Table'!A38,'01_Raw_Data'!N5:N1204) -> 246323.92
A39: Cash | B39: =SUMIF('01_Raw_Data'!H6:H1205,'03_Normal_Table'!A39,'01_Raw_Data'!N6:N1205) -> 259786.29
A40: x | B40: =SUMIF('01_Raw_Data'!H7:H1206,'03_Normal_Table'!A40,'01_Raw_Data'!N7:N1206) -> 1067.62

Sheet 05_Ctrl_T_Table
A2: Ctrl + T Table:
A3: Definition
A4: An Excel Table created by pressing Ctrl + T that provides automatic filtering, formatting, and dynamic expansion when new data is added.
A6: Product | B6: Quantity
A7: Monitor | B7: =SUMIF('01_Raw_Data'!D2:D1201,'05_Ctrl_T_Table'!A7,'01_Raw_Data'!E2:E1201) -> 480
A8: Phone | B8: =SUMIF('01_Raw_Data'!D3:D1202,'05_Ctrl_T_Table'!A8,'01_Raw_Data'!E3:E1202) -> 411
A9: Tablet | B9: =SUMIF('01_Raw_Data'!D4:D1203,'05_Ctrl_T_Table'!A9,'01_Raw_Data'!E4:E1203) -> 497
A10: Chair | B10: =SUMIF('01_Raw_Data'!D5:D1204,'05_Ctrl_T_Table'!A10,'01_Raw_Data'!E5:E1204) -> 562
A11: Printer | B11: =SUMIF('01_Raw_Data'!D6:D1205,'05_Ctrl_T_Table'!A11,'01_Raw_Data'!E6:E1205) -> 542
A12: Laptop | B12: =SUMIF('01_Raw_Data'!D8:D1207,'05_Ctrl_T_Table'!A13,'01_Raw_Data'!E8:E1207) -> 508
A13: Desk | B13: 165
A14: Abc | B14: 458
A22: Product | B22: Total Sales
A23: Monitor | B23: =SUMIF('01_Raw_Data'!D2:D1201,'05_Ctrl_T_Table'!A23,'01_Raw_Data'!N2:N1201) -> 175651.41
A24: Phone | B24: =SUMIF('01_Raw_Data'!D3:D1202,'05_Ctrl_T_Table'!A24,'01_Raw_Data'!N3:N1202) -> 151722.39
A25: Tablet | B25: =SUMIF('01_Raw_Data'!D4:D1203,'05_Ctrl_T_Table'!A25,'01_Raw_Data'!N4:N1203) -> 186568.95
A26: Chair | B26: =SUMIF('01_Raw_Data'!D5:D1204,'05_Ctrl_T_Table'!A26,'01_Raw_Data'!N5:N1204) -> 195620.11
A27: Printer | B27: =SUMIF('01_Raw_Data'!D6:D1205,'05_Ctrl_T_Table'!A27,'01_Raw_Data'!N6:N1205) -> 195612.61
A28: Laptop | B28: =SUMIF('01_Raw_Data'!D7:D1206,'05_Ctrl_T_Table'!A28,'01_Raw_Data'!N7:N1206) -> 192126.56
A29: Desk | B29: =SUMIF('01_Raw_Data'!D8:D1207,'05_Ctrl_T_Table'!A29,'01_Raw_Data'!N8:N1207) -> 167459.93
A30: Abc | B30: 1548892.4
A43: Payment Method | B43: Total Sales
A44: Debit Card | B44: =SUMIF('01_Raw_Data'!H2:H1201,Table3[[#This Row],[Payment Method]],'01_Raw_Data'!N2:N1201) -> 232361.18
A45: Online | B45: =SUMIF('01_Raw_Data'!H3:H1202,Table3[[#This Row],[Payment Method]],'01_Raw_Data'!N3:N1202) -> 262442.94
A46: Credit Card | B46: =SUMIF('01_Raw_Data'!H4:H1203,Table3[[#This Row],[Payment Method]],'01_Raw_Data'!N4:N1203) -> 262780.01
A47: Gift Card | B47: =SUMIF('01_Raw_Data'!H5:H1204,Table3[[#This Row],[Payment Method]],'01_Raw_Data'!N5:N1204) -> 246323.92
A48: Cash | B48: =SUMIF('01_Raw_Data'!H6:H1205,Table3[[#This Row],[Payment Method]],'01_Raw_Data'!N6:N1205) -> 259786.29
A49: x | B49: =SUMIF('01_Raw_Data'!H7:H1206,Table3[[#This Row],[Payment Method]],'01_Raw_Data'!N7:N1206) -> 1067.62

Sheet 06_Pivot_Table
A1: 05_Pivot_Table
A3: Definition
A4: A Pivot Table summarizes and analyzes large amounts of data by grouping and calculating values such as Sum, Average, and Count
A7: Row Labels | B7: Sum of Quantity | C7: Sum of TotalPrice
A8: Chair | B8: 562 | C8: 195620.11
A9: Desk | B9: 508 | C9: 167459.93
A10: Laptop | B10: 535 | C10: 192126.56
A11: Monitor | B11: 480 | C11: 175651.41
A12: Phone | B12: 411 | C12: 151722.39
A13: Printer | B13: 542 | C13: 195612.61
A14: Tablet | B14: 497 | C14: 186568.95
A15: Grand Total | B15: 3535 | C15: 1264762
